Traceback (most recent call last):
  File "C:\Users\janko\AppData\Local\Programs\Python\Python311\Lib\site-packages\jupyter_cache\executors\utils.py", line 58, in single_nb_execution
    executenb(
  File "C:\Users\janko\AppData\Local\Programs\Python\Python311\Lib\site-packages\nbclient\client.py", line 1305, in execute
    return NotebookClient(nb=nb, resources=resources, km=km, **kwargs).execute()
           ^^^^^^^^^^^^^^^^^^^^^^^^^^^^^^^^^^^^^^^^^^^^^^^^^^^^^^^^^^^^^^^^^^^^^
  File "C:\Users\janko\AppData\Local\Programs\Python\Python311\Lib\site-packages\jupyter_core\utils\__init__.py", line 168, in wrapped
    return loop.run_until_complete(inner)
           ^^^^^^^^^^^^^^^^^^^^^^^^^^^^^^
  File "C:\Users\janko\AppData\Local\Programs\Python\Python311\Lib\asyncio\base_events.py", line 653, in run_until_complete
    return future.result()
           ^^^^^^^^^^^^^^^
  File "C:\Users\janko\AppData\Local\Programs\Python\Python311\Lib\site-packages\nbclient\client.py", line 705, in async_execute
    await self.async_execute_cell(
  File "C:\Users\janko\AppData\Local\Programs\Python\Python311\Lib\site-packages\nbclient\client.py", line 1058, in async_execute_cell
    await self._check_raise_for_error(cell, cell_index, exec_reply)
  File "C:\Users\janko\AppData\Local\Programs\Python\Python311\Lib\site-packages\nbclient\client.py", line 914, in _check_raise_for_error
    raise CellExecutionError.from_cell_and_msg(cell, exec_reply_content)
nbclient.exceptions.CellExecutionError: An error occurred while executing the following cell:
------------------
def fun(x, dtype=np.float): # funkcija
    return np.exp(-dtype(x)).astype(dtype)
------------------


[1;31m---------------------------------------------------------------------------[0m
[1;31mAttributeError[0m                            Traceback (most recent call last)
Cell [1;32mIn[58], line 1[0m
[1;32m----> 1[0m [38;5;28;01mdef[39;00m [38;5;21mfun[39m(x, dtype[38;5;241m=[39m[43mnp[49m[38;5;241;43m.[39;49m[43mfloat[49m): [38;5;66;03m# funkcija[39;00m
[0;32m      2[0m     [38;5;28;01mreturn[39;00m np[38;5;241m.[39mexp([38;5;241m-[39mdtype(x))[38;5;241m.[39mastype(dtype)

File [1;32m~\AppData\Local\Programs\Python\Python311\Lib\site-packages\numpy\__init__.py:319[0m, in [0;36m__getattr__[1;34m(attr)[0m
[0;32m    314[0m     warnings[38;5;241m.[39mwarn(
[0;32m    315[0m         [38;5;124mf[39m[38;5;124m"[39m[38;5;124mIn the future `np.[39m[38;5;132;01m{[39;00mattr[38;5;132;01m}[39;00m[38;5;124m` will be defined as the [39m[38;5;124m"[39m
[0;32m    316[0m         [38;5;124m"[39m[38;5;124mcorresponding NumPy scalar.[39m[38;5;124m"[39m, [38;5;167;01mFutureWarning[39;00m, stacklevel[38;5;241m=[39m[38;5;241m2[39m)
[0;32m    318[0m [38;5;28;01mif[39;00m attr [38;5;129;01min[39;00m __former_attrs__:
[1;32m--> 319[0m     [38;5;28;01mraise[39;00m [38;5;167;01mAttributeError[39;00m(__former_attrs__[attr])
[0;32m    321[0m [38;5;28;01mif[39;00m attr [38;5;241m==[39m [38;5;124m'[39m[38;5;124mtesting[39m[38;5;124m'[39m:
[0;32m    322[0m     [38;5;28;01mimport[39;00m [38;5;21;01mnumpy[39;00m[38;5;21;01m.[39;00m[38;5;21;01mtesting[39;00m [38;5;28;01mas[39;00m [38;5;21;01mtesting[39;00m

[1;31mAttributeError[0m: module 'numpy' has no attribute 'float'.
`np.float` was a deprecated alias for the builtin `float`. To avoid this error in existing code, use `float` by itself. Doing this will not modify any behavior and is safe. If you specifically wanted the numpy scalar type, use `np.float64` here.
The aliases was originally deprecated in NumPy 1.20; for more details and guidance see the original release note at:
    https://numpy.org/devdocs/release/1.20.0-notes.html#deprecations

