Traceback (most recent call last):
  File "C:\Users\janko\AppData\Local\Programs\Python\Python311\Lib\site-packages\jupyter_cache\executors\utils.py", line 58, in single_nb_execution
    executenb(
  File "C:\Users\janko\AppData\Local\Programs\Python\Python311\Lib\site-packages\nbclient\client.py", line 1305, in execute
    return NotebookClient(nb=nb, resources=resources, km=km, **kwargs).execute()
           ^^^^^^^^^^^^^^^^^^^^^^^^^^^^^^^^^^^^^^^^^^^^^^^^^^^^^^^^^^^^^^^^^^^^^
  File "C:\Users\janko\AppData\Local\Programs\Python\Python311\Lib\site-packages\jupyter_core\utils\__init__.py", line 168, in wrapped
    return loop.run_until_complete(inner)
           ^^^^^^^^^^^^^^^^^^^^^^^^^^^^^^
  File "C:\Users\janko\AppData\Local\Programs\Python\Python311\Lib\asyncio\base_events.py", line 653, in run_until_complete
    return future.result()
           ^^^^^^^^^^^^^^^
  File "C:\Users\janko\AppData\Local\Programs\Python\Python311\Lib\site-packages\nbclient\client.py", line 705, in async_execute
    await self.async_execute_cell(
  File "C:\Users\janko\AppData\Local\Programs\Python\Python311\Lib\site-packages\nbclient\client.py", line 1058, in async_execute_cell
    await self._check_raise_for_error(cell, cell_index, exec_reply)
  File "C:\Users\janko\AppData\Local\Programs\Python\Python311\Lib\site-packages\nbclient\client.py", line 914, in _check_raise_for_error
    raise CellExecutionError.from_cell_and_msg(cell, exec_reply_content)
nbclient.exceptions.CellExecutionError: An error occurred while executing the following cell:
------------------
a = Pravokotnik(Å¡irina=3, viÅ¡ina=10)
a._Å¡irina
------------------


[1;31m---------------------------------------------------------------------------[0m
[1;31mAttributeError[0m                            Traceback (most recent call last)
Cell [1;32mIn[19], line 2[0m
[0;32m      1[0m a [38;5;241m=[39m Pravokotnik(Å¡irina[38;5;241m=[39m[38;5;241m3[39m, viÅ¡ina[38;5;241m=[39m[38;5;241m10[39m)
[1;32m----> 2[0m [43ma[49m[38;5;241;43m.[39;49m[43m_Å¡irina[49m

[1;31mAttributeError[0m: 'Pravokotnik' object has no attribute '_Å¡irina'

