Traceback (most recent call last):
  File "C:\Users\janko\AppData\Local\Programs\Python\Python312\Lib\site-packages\jupyter_core\utils\__init__.py", line 154, in wrapped
    asyncio.get_running_loop()
RuntimeError: no running event loop

During handling of the above exception, another exception occurred:

Traceback (most recent call last):
  File "C:\Users\janko\AppData\Local\Programs\Python\Python312\Lib\site-packages\jupyter_cache\executors\utils.py", line 58, in single_nb_execution
    executenb(
  File "C:\Users\janko\AppData\Local\Programs\Python\Python312\Lib\site-packages\nbclient\client.py", line 1319, in execute
    return NotebookClient(nb=nb, resources=resources, km=km, **kwargs).execute()
           ^^^^^^^^^^^^^^^^^^^^^^^^^^^^^^^^^^^^^^^^^^^^^^^^^^^^^^^^^^^^^^^^^^^^^
  File "C:\Users\janko\AppData\Local\Programs\Python\Python312\Lib\site-packages\jupyter_core\utils\__init__.py", line 158, in wrapped
    return loop.run_until_complete(inner)
           ^^^^^^^^^^^^^^^^^^^^^^^^^^^^^^
  File "C:\Users\janko\AppData\Local\Programs\Python\Python312\Lib\asyncio\base_events.py", line 687, in run_until_complete
    return future.result()
           ^^^^^^^^^^^^^^^
  File "C:\Users\janko\AppData\Local\Programs\Python\Python312\Lib\site-packages\nbclient\client.py", line 709, in async_execute
    await self.async_execute_cell(
  File "C:\Users\janko\AppData\Local\Programs\Python\Python312\Lib\site-packages\nbclient\client.py", line 1062, in async_execute_cell
    await self._check_raise_for_error(cell, cell_index, exec_reply)
  File "C:\Users\janko\AppData\Local\Programs\Python\Python312\Lib\site-packages\nbclient\client.py", line 918, in _check_raise_for_error
    raise CellExecutionError.from_cell_and_msg(cell, exec_reply_content)
nbclient.exceptions.CellExecutionError: An error occurred while executing the following cell:
------------------
# ReÅ¡imo sistem
P = np.linalg.solve(A, b)
P
------------------


[31m---------------------------------------------------------------------------[39m
[31mUFuncTypeError[39m                            Traceback (most recent call last)
[36mCell[39m[36m [39m[32mIn[10][39m[32m, line 2[39m
[32m      1[39m [38;5;66;03m# ReÅ¡imo sistem[39;00m
[32m----> [39m[32m2[39m P = [43mnp[49m[43m.[49m[43mlinalg[49m[43m.[49m[43msolve[49m[43m([49m[43mA[49m[43m,[49m[43m [49m[43mb[49m[43m)[49m
[32m      3[39m P

[36mFile [39m[32m~\AppData\Local\Programs\Python\Python312\Lib\site-packages\numpy\linalg\_linalg.py:410[39m, in [36msolve[39m[34m(a, b)[39m
[32m    407[39m signature = [33m'[39m[33mDD->D[39m[33m'[39m [38;5;28;01mif[39;00m isComplexType(t) [38;5;28;01melse[39;00m [33m'[39m[33mdd->d[39m[33m'[39m
[32m    408[39m [38;5;28;01mwith[39;00m errstate(call=_raise_linalgerror_singular, invalid=[33m'[39m[33mcall[39m[33m'[39m,
[32m    409[39m               over=[33m'[39m[33mignore[39m[33m'[39m, divide=[33m'[39m[33mignore[39m[33m'[39m, under=[33m'[39m[33mignore[39m[33m'[39m):
[32m--> [39m[32m410[39m     r = [43mgufunc[49m[43m([49m[43ma[49m[43m,[49m[43m [49m[43mb[49m[43m,[49m[43m [49m[43msignature[49m[43m=[49m[43msignature[49m[43m)[49m
[32m    412[39m [38;5;28;01mreturn[39;00m wrap(r.astype(result_t, copy=[38;5;28;01mFalse[39;00m))

[31mUFuncTypeError[39m: Cannot cast ufunc 'solve1' input 0 from dtype('O') to dtype('float64') with casting rule 'same_kind'

