Traceback (most recent call last):
  File "C:\Users\janko\AppData\Local\Programs\Python\Python312\Lib\site-packages\jupyter_core\utils\__init__.py", line 154, in wrapped
    asyncio.get_running_loop()
RuntimeError: no running event loop

During handling of the above exception, another exception occurred:

Traceback (most recent call last):
  File "C:\Users\janko\AppData\Local\Programs\Python\Python312\Lib\site-packages\jupyter_cache\executors\utils.py", line 58, in single_nb_execution
    executenb(
  File "C:\Users\janko\AppData\Local\Programs\Python\Python312\Lib\site-packages\nbclient\client.py", line 1319, in execute
    return NotebookClient(nb=nb, resources=resources, km=km, **kwargs).execute()
           ^^^^^^^^^^^^^^^^^^^^^^^^^^^^^^^^^^^^^^^^^^^^^^^^^^^^^^^^^^^^^^^^^^^^^
  File "C:\Users\janko\AppData\Local\Programs\Python\Python312\Lib\site-packages\jupyter_core\utils\__init__.py", line 158, in wrapped
    return loop.run_until_complete(inner)
           ^^^^^^^^^^^^^^^^^^^^^^^^^^^^^^
  File "C:\Users\janko\AppData\Local\Programs\Python\Python312\Lib\asyncio\base_events.py", line 687, in run_until_complete
    return future.result()
           ^^^^^^^^^^^^^^^
  File "C:\Users\janko\AppData\Local\Programs\Python\Python312\Lib\site-packages\nbclient\client.py", line 709, in async_execute
    await self.async_execute_cell(
  File "C:\Users\janko\AppData\Local\Programs\Python\Python312\Lib\site-packages\nbclient\client.py", line 1062, in async_execute_cell
    await self._check_raise_for_error(cell, cell_index, exec_reply)
  File "C:\Users\janko\AppData\Local\Programs\Python\Python312\Lib\site-packages\nbclient\client.py", line 918, in _check_raise_for_error
    raise CellExecutionError.from_cell_and_msg(cell, exec_reply_content)
nbclient.exceptions.CellExecutionError: An error occurred while executing the following cell:
------------------
from scipy.misc import central_diff_weights as cdw
------------------

----- stderr -----
C:\Users\janko\AppData\Local\Temp\ipykernel_10232\2572490975.py:1: DeprecationWarning: scipy.misc is deprecated and will be removed in 2.0.0
  from scipy.misc import central_diff_weights as cdw
------------------

[31m---------------------------------------------------------------------------[39m
[31mImportError[39m                               Traceback (most recent call last)
[36mCell[39m[36m [39m[32mIn[16][39m[32m, line 1[39m
[32m----> [39m[32m1[39m [38;5;28;01mfrom[39;00m[38;5;250m [39m[34;01mscipy[39;00m[34;01m.[39;00m[34;01mmisc[39;00m[38;5;250m [39m[38;5;28;01mimport[39;00m central_diff_weights [38;5;28;01mas[39;00m cdw

[31mImportError[39m: cannot import name 'central_diff_weights' from 'scipy.misc' (C:\Users\janko\AppData\Local\Programs\Python\Python312\Lib\site-packages\scipy\misc\__init__.py)

